Workbook
Name Slicer_Department: #N/A
Name Slicer_Grade: #N/A

Sheet DASHBOARD
A1: ATTRITION DASHBOARD | F1: =GETPIVOTDATA("[Measures].[Count of Employee Name]",'CALCULATION 0'!$A$3) -> 99 | H1: =GETPIVOTDATA("[Measures].[Count of Employee Name]",'CALCULATION 0'!$D$3) -> 17 | J1: =GETPIVOTDATA("[Measures].[Count of Employee Name]",'CALCULATION 0'!$J$4) -> 15 | L1: =GETPIVOTDATA("[Measures].[Count of Employee Name]",'CALCULATION 0'!$G$4) -> 2 | N1: ='CALCULATION 0'!B9 -> 0.13953488
F2: TOTAL EMP COUNT | H2: TOTAL EXIT | J2: VOLUNTARY EXIT | L2: INVOLUNTARY EXIT | N2: ATTRITION %

Sheet CALCULATION 1

Sheet CALCULATION 2

Sheet CALCULATION 0
A1: Status | B1: Active | D1: Status | E1: Inactive | G1: Status | H1: Inactive | J1: Status | K1: Inactive
G2: Exit Type | H2: Involuntary | J2: Exit Type | K2: Voluntary
A3: Count of Employee Name | D3: Count of Employee Name
A4: 99 | D4: 17 | G4: Count of Employee Name | J4: Count of Employee Name
G5: 2 | J5: 15
A7: HC AS ON 31 DEC-2024 | B7: 116
A8: ACTIVE COUNT | B8: =GETPIVOTDATA("[Measures].[Count of Employee Name]",$A$3) -> 99
A9: ATTRITION % | B9: =GETPIVOTDATA("[Measures].[Count of Employee Name]",$J$4)/((B7+B8)/2) -> 0.13953488
A12: Status | B12: Inactive | D12: Status | E12: Inactive | G12: Status | H12: Inactive
A13: Exit Type | B13: Voluntary | D13: Exit Type | E13: Voluntary | G13: Exit Type | H13: Voluntary
A15: Row Labels | B15: Count of Employee Name | D15: Row Labels | E15: Count of Employee Name | G15: Row Labels | H15: Count of Employee Name
A16: 1 to 3 Yrs | B16: 5 | D16: Better Opportunity | E16: 9 | G16: 2025
A17: 3 to 6 Yrs | B17: 7 | D17: Conflict with Manager/Colleagues | E17: 2 | G17: January | H17: 1
A18: 6 to 9 Yrs | B18: 3 | D18: Health Reasons | E18: 2 | G18: February | H18: 1
A19: Grand Total | B19: 15 | D19: Relocation | E19: 2 | G19: March | H19: 1
D20: Grand Total | E20: 15 | G20: April | H20: 1
G21: May | H21: 2
G22: June | H22: 3
G23: July | H23: 2
G24: September | H24: 1
G25: October | H25: 1
G26: November | H26: 1
G27: December | H27: 1
G28: Grand Total | H28: 15

Sheet Data
A1: Sr.No | B1: Employee Code | C1: Employee Name | D1: Gender | E1: Grade | F1: Department | G1: Status | H1: DOJ | I1: Exit Date | J1: Exit Type | K1: Exit Reason | L1: Manager Name | M1: Tenure | N1: Tenure Group
A2: 1 | B2: 10104 | C2: Jack McFarland | D2: M | E2: G5 | F2: Marketing | G2: =IF(ISBLANK(Exit_Data[[#This Row],[Exit Date]]),"Active","Inactive") -> Active | H2: 43905 | L2: Emily Cooper | M2: =(TODAY()-Exit_Data[[#This Row],[DOJ]])/365.25 -> 6.2970568 | N2: =_xlfn.IFS(Exit_Data[[#This Row],[Tenure]]>9,"9+ Yrs",Exit_Data[[#This Row],[Tenure]]>6,"6 to 9 Yrs",Exit_Data[[#This Row],[Tenure]]>3,"3 to 6 Yrs",Exit_Data[[#This Row],[Tenure]]>1,"1 to 3 Yrs",Exit_Data[[#This Row],[Tenure]]>0,"0 to 1 Yr") -> 6 to 9 Yrs
A3: 2 | B3: 10105 | C3: Rose Nylund | D3: F | E3: G4 | F3: Sales | G3: =IF(ISBLANK(Exit_Data[[#This Row],[Exit Date]]),"Active","Inactive") -> Active | H3: 44399 | L3: Kate Sharma | M3: =(TODAY()-Exit_Data[[#This Row],[DOJ]])/365.25 -> 4.9445585 | N3: =_xlfn.IFS(Exit_Data[[#This Row],[Tenure]]>9,"9+ Yrs",Exit_Data[[#This Row],[Tenure]]>6,"6 to 9 Yrs",Exit_Data[[#This Row],[Tenure]]>3,"3 to 6 Yrs",Exit_Data[[#This Row],[Tenure]]>1,"1 to 3 Yrs",Exit_Data[[#This Row],[Tenure]]>0,"0 to 1 Yr") -> 3 to 6 Yrs
A4: 3 | B4: 10106 | C4: Parth Josh | D4: M | E4: G5 | F4: Finance | G4: =IF(ISBLANK(Exit_Data[[#This Row],[Exit Date]]),"Active","Inactive") -> Active | H4: 44571 | L4: Anthony Bridgerton | M4: =(TODAY()-Exit_Data[[#This Row],[DOJ]])/365.25 -> 4.4736482 | N4: =_xlfn.IFS(Exit_Data[[#This Row],[Tenure]]>9,"9+ Yrs",Exit_Data[[#This Row],[Tenure]]>6,"6 to 9 Yrs",Exit_Data[[#This Row],[Tenure]]>3,"3 to 6 Yrs",Exit_Data[[#This Row],[Tenure]]>1,"1 to 3 Yrs",Exit_Data[[#This Row],[Tenure]]>0,"0 to 1 Yr") -> 3 to 6 Yrs
A5: 4 | B5: 10107 | C5: Olivia Pope | D5: F | E5: G4 | F5: IT | G5: =IF(ISBLANK(Exit_Data[[#This Row],[Exit Date]]),"Active","Inactive") -> Active | H5: 45782 | L5: Wally Clark | M5: =(TODAY()-Exit_Data[[#This Row],[DOJ]])/365.25 -> 1.1581109 | N5: =_xlfn.IFS(Exit_Data[[#This Row],[Tenure]]>9,"9+ Yrs",Exit_Data[[#This Row],[Tenure]]>6,"6 to 9 Yrs",Exit_Data[[#This Row],[Tenure]]>3,"3 to 6 Yrs",Exit_Data[[#This Row],[Tenure]]>1,"1 to 3 Yrs",Exit_Data[[#This Row],[Tenure]]>0,"0 to 1 Yr") -> 1 to 3 Yrs
A6: 5 | B6: 10108 | C6: Walter White | D6: M | E6: G5 | F6: Marketing | G6: =IF(ISBLANK(Exit_Data[[#This Row],[Exit Date]]),"Active","Inactive") -> Active | H6: 45156 | L6: Emily Cooper | M6: =(TODAY()-Exit_Data[[#This Row],[DOJ]])/365.25 -> 2.8720055 | N6: =_xlfn.IFS(Exit_Data[[#This Row],[Tenure]]>9,"9+ Yrs",Exit_Data[[#This Row],[Tenure]]>6,"6 to 9 Yrs",Exit_Data[[#This Row],[Tenure]]>3,"3 to 6 Yrs",Exit_Data[[#This Row],[Tenure]]>1,"1 to 3 Yrs",Exit_Data[[#This Row],[Tenure]]>0,"0 to 1 Yr") -> 1 to 3 Yrs
A7: 6 | B7: 10109 | C7: Prafulla Sohoni | D7: M | E7: G3 | F7: IT | G7: =IF(ISBLANK(Exit_Data[[#This Row],[Exit Date]]),"Active","Inactive") -> Active | H7: 44239 | L7: Wally Clark | M7: =(TODAY()-Exit_Data[[#This Row],[DOJ]])/365.25 -> 5.3826146 | N7: =_xlfn.IFS(Exit_Data[[#This Row],[Tenure]]>9,"9+ Yrs",Exit_Data[[#This Row],[Tenure]]>6,"6 to 9 Yrs",Exit_Data[[#This Row],[Tenure]]>3,"3 to 6 Yrs",Exit_Data[[#This Row],[Tenure]]>1,"1 to 3 Yrs",Exit_Data[[#This Row],[Tenure]]>0,"0 to 1 Yr") -> 3 to 6 Yrs
A8: 7 | B8: 10110 | C8: Jessica Fletcher | D8: F | E8: G3 | F8: Marketing | G8: =IF(ISBLANK(Exit_Data[[#This Row],[Exit Date]]),"Active","Inactive") -> Inactive | H8: 44104 | I8: 45823 | J8: Voluntary | K8: Health Reasons | L8: Camille Razat | M8: =(TODAY()-Exit_Data[[#This Row],[DOJ]])/365.25 -> 5.7522245 | N8: =_xlfn.IFS(Exit_Data[[#This Row],[Tenure]]>9,"9+ Yrs",Exit_Data[[#This Row],[Tenure]]>6,"6 to 9 Yrs",Exit_Data[[#This Row],[Tenure]]>3,"3 to 6 Yrs",Exit_Data[[#This Row],[Tenure]]>1,"1 to 3 Yrs",Exit_Data[[#This Row],[Tenure]]>0,"0 to 1 Yr") -> 3 to 6 Yrs
A9: 8 | B9: 10111 | C9: Jack Tripper | D9: M | E9: G3 | F9: Sales | G9: =IF(ISBLANK(Exit_Data[[#This Row],[Exit Date]]),"Active","Inactive") -> Inactive | H9: 44876 | I9: 45667 | J9: Voluntary | K9: Relocation | L9: Kate Sharma | M9: =(TODAY()-Exit_Data[[#This Row],[DOJ]])/365.25 -> 3.6386037 | N9: =_xlfn.IFS(Exit_Data[[#This Row],[Tenure]]>9,"9+ Yrs",Exit_Data[[#This Row],[Tenure]]>6,"6 to 9 Yrs",Exit_Data[[#This Row],[Tenure]]>3,"3 to 6 Yrs",Exit_Data[[#This Row],[Tenure]]>1,"1 to 3 Yrs",Exit_Data[[#This Row],[Tenure]]>0,"0 to 1 Yr") -> 3 to 6 Yrs
A10: 9 | B10: 10112 | C10: Sam Malone | D10: M | E10: G3 | F10: IT | G10: =IF(ISBLANK(Exit_Data[[#This Row],[Exit Date]]),"Active","Inactive") -> Active | H10: 44190 | L10: Wally Clark | M10: =(TODAY()-Exit_Data[[#This Row],[DOJ]])/365.25 -> 5.5167693 | N10: =_xlfn.IFS(Exit_Data[[#This Row],[Tenure]]>9,"9+ Yrs",Exit_Data[[#This Row],[Tenure]]>6,"6 to 9 Yrs",Exit_Data[[#This Row],[Tenure]]>3,"3 to 6 Yrs",Exit_Data[[#This Row],[Tenure]]>1,"1 to 3 Yrs",Exit_Data[[#This Row],[Tenure]]>0,"0 to 1 Yr") -> 3 to 6 Yrs
A11: 10 | B11: 10113 | C11: Elaine Benes | D11: F | E11: G2 | F11: IT | G11: =IF(ISBLANK(Exit_Data[[#This Row],[Exit Date]]),"Active","Inactive") -> Inactive | H11: 44300 | I11: 45915 | J11: Involuntary | K11: Performance | L11: Wally Clark | M11: =(TODAY()-Exit_Data[[#This Row],[DOJ]])/365.25 -> 5.2156057 | N11: =_xlfn.IFS(Exit_Data[[#This Row],[Tenure]]>9,"9+ Yrs",Exit_Data[[#This Row],[Tenure]]>6,"6 to 9 Yrs",Exit_Data[[#This Row],[Tenure]]>3,"3 to 6 Yrs",Exit_Data[[#This Row],[Tenure]]>1,"1 to 3 Yrs",Exit_Data[[#This Row],[Tenure]]>0,"0 to 1 Yr") -> 3 to 6 Yrs
A12: 11 | B12: 10114 | C12: Omar Little | D12: M | E12: G4 | F12: Marketing | G12: =IF(ISBLANK(Exit_Data[[#This Row],[Exit Date]]),"Active","Inactive") -> Active | H12: 44988 | L12: Emily Cooper | M12: =(TODAY()-Exit_Data[[#This Row],[DOJ]])/365.25 -> 3.3319644 | N12: =_xlfn.IFS(Exit_Data[[#This Row],[Tenure]]>9,"9+ Yrs",Exit_Data[[#This Row],[Tenure]]>6,"6 to 9 Yrs",Exit_Data[[#This Row],[Tenure]]>3,"3 to 6 Yrs",Exit_Data[[#This Row],[Tenure]]>1,"1 to 3 Yrs",Exit_Data[[#This Row],[Tenure]]>0,"0 to 1 Yr") -> 3 to 6 Yrs
A13: 12 | B13: 10115 | C13: Archie Bunker | D13: M | E13: G2 | F13: Marketing | G13: =IF(ISBLANK(Exit_Data[[#This Row],[Exit Date]]),"Active","Inactive") -> Active | H13: 43839 | L13: Emily Cooper | M13: =(TODAY()-Exit_Data[[#This Row],[DOJ]])/365.25 -> 6.477755 | N13: =_xlfn.IFS(Exit_Data[[#This Row],[Tenure]]>9,"9+ Yrs",Exit_Data[[#This Row],[Tenure]]>6,"6 to 9 Yrs",Exit_Data[[#This Row],[Tenure]]>3,"3 to 6 Yrs",Exit_Data[[#This Row],[Tenure]]>1,"1 to 3 Yrs",Exit_Data[[#This Row],[Tenure]]>0,"0 to 1 Yr") -> 6 to 9 Yrs
A14: 13 | B14: 10116 | C14: Mary Ann Summers | D14: F | E14: G2 | F14: Sales | G14: =IF(ISBLANK(Exit_Data[[#This Row],[Exit Date]]),"Active","Inactive") -> Active | H14: 44731 | L14: Kate Sharma | M14: =(TODAY()-Exit_Data[[#This Row],[DOJ]])/365.25 -> 4.0355921 | N14: =_xlfn.IFS(Exit_Data[[#This Row],[Tenure]]>9,"9+ Yrs",Exit_Data[[#This Row],[Tenure]]>6,"6 to 9 Yrs",Exit_Data[[#This Row],[Tenure]]>3,"3 to 6 Yrs",Exit_Data[[#This Row],[Tenure]]>1,"1 to 3 Yrs",Exit_Data[[#This Row],[Tenure]]>0,"0 to 1 Yr") -> 3 to 6 Yrs
A15: 14 | B15: 10117 | C15: Leslie Knope | D15: F | E15: G5 | F15: Marketing | G15: =IF(ISBLANK(Exit_Data[[#This Row],[Exit Date]]),"Active","Inactive") -> Active | H15: 44404 | L15: Emily Cooper | M15: =(TODAY()-Exit_Data[[#This Row],[DOJ]])/365.25 -> 4.9308693 | N15: =_xlfn.IFS(Exit_Data[[#This Row],[Tenure]]>9,"9+ Yrs",Exit_Data[[#This Row],[Tenure]]>6,"6 to 9 Yrs",Exit_Data[[#This Row],[Tenure]]>3,"3 to 6 Yrs",Exit_Data[[#This Row],[Tenure]]>1,"1 to 3 Yrs",Exit_Data[[#This Row],[Tenure]]>0,"0 to 1 Yr") -> 3 to 6 Yrs
A16: 15 | B16: 10118 | C16: Dexter Morgan | D16: M | E16: G1 | F16: Sales | G16: =IF(ISBLANK(Exit_Data[[#This Row],[Exit Date]]),"Active","Inactive") -> Active | H16: 44051 | L16: Kate Sharma | M16: =(TODAY()-Exit_Data[[#This Row],[DOJ]])/365.25 -> 5.8973306 | N16: =_xlfn.IFS(Exit_Data[[#This Row],[Tenure]]>9,"9+ Yrs",Exit_Data[[#This Row],[Tenure]]>6,"6 to 9 Yrs",Exit_Data[[#This Row],[Tenure]]>3,"3 to 6 Yrs",Exit_Data[[#This Row],[Tenure]]>1,"1 to 3 Yrs",Exit_Data[[#This Row],[Tenure]]>0,"0 to 1 Yr") -> 3 to 6 Yrs
A17: 16 | B17: 10119 | C17: Miranda Bailey | D17: F | E17: G2 | F17: IT | G17: =IF(ISBLANK(Exit_Data[[#This Row],[Exit Date]]),"Active","Inactive") -> Active | H17: 45001 | L17: Simon Elroy | M17: =(TODAY()-Exit_Data[[#This Row],[DOJ]])/365.25 -> 3.2963723 | N17: =_xlfn.IFS(Exit_Data[[#This Row],[Tenure]]>9,"9+ Yrs",Exit_Data[[#This Row],[Tenure]]>6,"6 to 9 Yrs",Exit_Data[[#This Row],[Tenure]]>3,"3 to 6 Yrs",Exit_Data[[#This Row],[Tenure]]>1,"1 to 3 Yrs",Exit_Data[[#This Row],[Tenure]]>0,"0 to 1 Yr") -> 3 to 6 Yrs
A18: 17 | B18: 10120 | C18: Michael Scott | D18: M | E18: G5 | F18: Marketing | G18: =IF(ISBLANK(Exit_Data[[#This Row],[Exit Date]]),"Active","Inactive") -> Active | H18: 43831 | L18: Emily Cooper | M18: =(TODAY()-Exit_Data[[#This Row],[DOJ]])/365.25 -> 6.4996578 | N18: =_xlfn.IFS(Exit_Data[[#This Row],[Tenure]]>9,"9+ Yrs",Exit_Data[[#This Row],[Tenure]]>6,"6 to 9 Yrs",Exit_Data[[#This Row],[Tenure]]>3,"3 to 6 Yrs",Exit_Data[[#This Row],[Tenure]]>1,"1 to 3 Yrs",Exit_Data[[#This Row],[Tenure]]>0,"0 to 1 Yr") -> 6 to 9 Yrs
A19: 18 | B19: 10121 | C19: Marcia Brad | D19: F | E19: G5 | F19: Marketing | G19: =IF(ISBLANK(Exit_Data[[#This Row],[Exit Date]]),"Active","Inactive") -> Active | H19: 44328 | L19: Camille Razat | M19: =(TODAY()-Exit_Data[[#This Row],[DOJ]])/365.25 -> 5.1389459 | N19: =_xlfn.IFS(Exit_Data[[#This Row],[Tenure]]>9,"9+ Yrs",Exit_Data[[#This Row],[Tenure]]>6,"6 to 9 Yrs",Exit_Data[[#This Row],[Tenure]]>3,"3 to 6 Yrs",Exit_Data[[#This Row],[Tenure]]>1,"1 to 3 Yrs",Exit_Data[[#This Row],[Tenure]]>0,"0 to 1 Yr") -> 3 to 6 Yrs
A20: 19 | B20: 10122 | C20: Lucy Ricardo | D20: F | E20: G5 | F20: Sales | G20: =IF(ISBLANK(Exit_Data[[#This Row],[Exit Date]]),"Active","Inactive") -> Active | H20: 44857 | L20: Kate Sharma | M20: =(TODAY()-Exit_Data[[#This Row],[DOJ]])/365.25 -> 3.6906229 | N20: =_xlfn.IFS(Exit_Data[[#This Row],[Tenure]]>9,"9+ Yrs",Exit_Data[[#This Row],[Tenure]]>6,"6 to 9 Yrs",Exit_Data[[#This Row],[Tenure]]>3,"3 to 6 Yrs",Exit_Data[[#This Row],[Tenure]]>1,"1 to 3 Yrs",Exit_Data[[#This Row],[Tenure]]>0,"0 to 1 Yr") -> 3 to 6 Yrs
A21: 20 | B21: 10123 | C21: Missy Cooper | D21: F | E21: G2 | F21: Sales | G21: =IF(ISBLANK(Exit_Data[[#This Row],[Exit Date]]),"Active","Inactive") -> Active | H21: 45326 | L21: Kate Sharma | M21: =(TODAY()-Exit_Data[[#This Row],[DOJ]])/365.25 -> 2.4065708 | N21: =_xlfn.IFS(Exit_Data[[#This Row],[Tenure]]>9,"9+ Yrs",Exit_Data[[#This Row],[Tenure]]>6,"6 to 9 Yrs",Exit_Data[[#This Row],[Tenure]]>3,"3 to 6 Yrs",Exit_Data[[#This Row],[Tenure]]>1,"1 to 3 Yrs",Exit_Data[[#This Row],[Tenure]]>0,"0 to 1 Yr") -> 1 to 3 Yrs
A22: 21 | B22: 10124 | C22: Connie Tucker | D22: F | E22: G2 | F22: Sales | G22: =IF(ISBLANK(Exit_Data[[#This Row],[Exit Date]]),"Active","Inactive") -> Active | H22: 45289 | L22: Margo Banks | M22: =(TODAY()-Exit_Data[[#This Row],[DOJ]])/365.25 -> 2.5078713 | N22: =_xlfn.IFS(Exit_Data[[#This Row],[Tenure]]>9,"9+ Yrs",Exit_Data[[#This Row],[Tenure]]>6,"6 to 9 Yrs",Exit_Data[[#This Row],[Tenure]]>3,"3 to 6 Yrs",Exit_Data[[#This Row],[Tenure]]>1,"1 to 3 Yrs",Exit_Data[[#This Row],[Tenure]]>0,"0 to 1 Yr") -> 1 to 3 Yrs
A23: 22 | B23: 10125 | C23: John Sturgis | D23: M | E23: G1 | F23: Finance | G23: =IF(ISBLANK(Exit_Data[[#This Row],[Exit Date]]),"Active","Inactive") -> Active | H23: 43999 | L23: Mindy Chen | M23: =(TODAY()-Exit_Data[[#This Row],[DOJ]])/365.25 -> 6.0396988 | N23: =_xlfn.IFS(Exit_Data[[#This Row],[Tenure]]>9,"9+ Yrs",Exit_Data[[#This Row],[Tenure]]>6,"6 to 9 Yrs",Exit_Data[[#This Row],[Tenure]]>3,"3 to 6 Yrs",Exit_Data[[#This Row],[Tenure]]>1,"1 to 3 Yrs",Exit_Data[[#This Row],[Tenure]]>0,"0 to 1 Yr") -> 6 to 9 Yrs
... A33: 32 | B33: 10135 | C33: Richard Burke | D33: M | E33: G1 | F33: IT | G33: =IF(ISBLANK(Exit_Data[[#This Row],[Exit Date]]),"Active","Inactive") -> Active | H33: 45229 | L33: Wally Clark | M33: =(TODAY()-Exit_Data[[#This Row],[DOJ]])/365.25 -> 2.6721424 | N33: =_xlfn.IFS(Exit_Data[[#This Row],[Tenure]]>9,"9+ Yrs",Exit_Data[[#This Row],[Tenure]]>6,"6 to 9 Yrs",Exit_Data[[#This Row],[Tenure]]>3,"3 to 6 Yrs",Exit_Data[[#This Row],[Tenure]]>1,"1 to 3 Yrs",Exit_Data[[#This Row],[Tenure]]>0,"0 to 1 Yr") -> 1 to 3 Yrs
A34: 33 | B34: 10136 | C34: Ted Mosby | D34: M | E34: G2 | F34: IT | G34: =IF(ISBLANK(Exit_Data[[#This Row],[Exit Date]]),"Active","Inactive") -> Inactive | H34: 44563 | I34: 45696 | J34: Voluntary | K34: Better Opportunity | L34: Simon Elroy | M34: =(TODAY()-Exit_Data[[#This Row],[DOJ]])/365.25 -> 4.495551 | N34: =_xlfn.IFS(Exit_Data[[#This Row],[Tenure]]>9,"9+ Yrs",Exit_Data[[#This Row],[Tenure]]>6,"6 to 9 Yrs",Exit_Data[[#This Row],[Tenure]]>3,"3 to 6 Yrs",Exit_Data[[#This Row],[Tenure]]>1,"1 to 3 Yrs",Exit_Data[[#This Row],[Tenure]]>0,"0 to 1 Yr") -> 3 to 6 Yrs
A35: 34 | B35: 10137 | C35: Robin Scherbatsky | D35: F | E35: G3 | F35: IT | G35: =IF(ISBLANK(Exit_Data[[#This Row],[Exit Date]]),"Active","Inactive") -> Active | H35: 44426 | L35: Simon Elroy | M35: =(TODAY()-Exit_Data[[#This Row],[DOJ]])/365.25 -> 4.8706366 | N35: =_xlfn.IFS(Exit_Data[[#This Row],[Tenure]]>9,"9+ Yrs",Exit_Data[[#This Row],[Tenure]]>6,"6 to 9 Yrs",Exit_Data[[#This Row],[Tenure]]>3,"3 to 6 Yrs",Exit_Data[[#This Row],[Tenure]]>1,"1 to 3 Yrs",Exit_Data[[#This Row],[Tenure]]>0,"0 to 1 Yr") -> 3 to 6 Yrs
A36: 35 | B36: 10138 | C36: Marshall Eriksen | D36: M | E36: G1 | F36: Marketing | G36: =IF(ISBLANK(Exit_Data[[#This Row],[Exit Date]]),"Active","Inactive") -> Active | H36: 43897 | L36: Camille Razat | M36: =(TODAY()-Exit_Data[[#This Row],[DOJ]])/365.25 -> 6.3189596 | N36: =_xlfn.IFS(Exit_Data[[#This Row],[Tenure]]>9,"9+ Yrs",Exit_Data[[#This Row],[Tenure]]>6,"6 to 9 Yrs",Exit_Data[[#This Row],[Tenure]]>3,"3 to 6 Yrs",Exit_Data[[#This Row],[Tenure]]>1,"1 to 3 Yrs",Exit_Data[[#This Row],[Tenure]]>0,"0 to 1 Yr") -> 6 to 9 Yrs
A37: 36 | B37: 10139 | C37: Lily Aldrin | D37: F | E37: G3 | F37: Marketing | G37: =IF(ISBLANK(Exit_Data[[#This Row],[Exit Date]]),"Active","Inactive") -> Active | H37: 44907 | L37: Camille Razat | M37: =(TODAY()-Exit_Data[[#This Row],[DOJ]])/365.25 -> 3.5537303 | N37: =_xlfn.IFS(Exit_Data[[#This Row],[Tenure]]>9,"9+ Yrs",Exit_Data[[#This Row],[Tenure]]>6,"6 to 9 Yrs",Exit_Data[[#This Row],[Tenure]]>3,"3 to 6 Yrs",Exit_Data[[#This Row],[Tenure]]>1,"1 to 3 Yrs",Exit_Data[[#This Row],[Tenure]]>0,"0 to 1 Yr") -> 3 to 6 Yrs
A38: 37 | B38: 10140 | C38: Barney Stinson | D38: M | E38: G4 | F38: Sales | G38: =IF(ISBLANK(Exit_Data[[#This Row],[Exit Date]]),"Active","Inactive") -> Inactive | H38: 43922 | I38: 45853 | J38: Voluntary | K38: Better Opportunity | L38: Margo Banks | M38: =(TODAY()-Exit_Data[[#This Row],[DOJ]])/365.25 -> 6.2505133 | N38: =_xlfn.IFS(Exit_Data[[#This Row],[Tenure]]>9,"9+ Yrs",Exit_Data[[#This Row],[Tenure]]>6,"6 to 9 Yrs",Exit_Data[[#This Row],[Tenure]]>3,"3 to 6 Yrs",Exit_Data[[#This Row],[Tenure]]>1,"1 to 3 Yrs",Exit_Data[[#This Row],[Tenure]]>0,"0 to 1 Yr") -> 6 to 9 Yrs
A39: 38 | B39: 10141 | C39: Stella Zinman | D39: F | E39: G3 | F39: IT | G39: =IF(ISBLANK(Exit_Data[[#This Row],[Exit Date]]),"Active","Inactive") -> Inactive | H39: 45071 | I39: 45940 | J39: Voluntary | K39: Better Opportunity | L39: Simon Elroy | M39: =(TODAY()-Exit_Data[[#This Row],[DOJ]])/365.25 -> 3.1047228 | N39: =_xlfn.IFS(Exit_Data[[#This Row],[Tenure]]>9,"9+ Yrs",Exit_Data[[#This Row],[Tenure]]>6,"6 to 9 Yrs",Exit_Data[[#This Row],[Tenure]]>3,"3 to 6 Yrs",Exit_Data[[#This Row],[Tenure]]>1,"1 to 3 Yrs",Exit_Data[[#This Row],[Tenure]]>0,"0 to 1 Yr") -> 3 to 6 Yrs
A40: 39 | B40: 10142 | C40: Quinn Garvey | D40: M | E40: G2 | F40: sales | G40: =IF(ISBLANK(Exit_Data[[#This Row],[Exit Date]]),"Active","Inactive") -> Active | H40: 44448 | L40: Margo Banks | M40: =(TODAY()-Exit_Data[[#This Row],[DOJ]])/365.25 -> 4.8104038 | N40: =_xlfn.IFS(Exit_Data[[#This Row],[Tenure]]>9,"9+ Yrs",Exit_Data[[#This Row],[Tenure]]>6,"6 to 9 Yrs",Exit_Data[[#This Row],[Tenure]]>3,"3 to 6 Yrs",Exit_Data[[#This Row],[Tenure]]>1,"1 to 3 Yrs",Exit_Data[[#This Row],[Tenure]]>0,"0 to 1 Yr") -> 3 to 6 Yrs
A41: 40 | B41: 10143 | C41: Harvey Specter | D41: M | E41: G4 | F41: Marketing | G41: =IF(ISBLANK(Exit_Data[[#This Row],[Exit Date]]),"Active","Inactive") -> Active | H41: 43841 | L41: Camille Razat | M41: =(TODAY()-Exit_Data[[#This Row],[DOJ]])/365.25 -> 6.4722793 | N41: =_xlfn.IFS(Exit_Data[[#This Row],[Tenure]]>9,"9+ Yrs",Exit_Data[[#This Row],[Tenure]]>6,"6 to 9 Yrs",Exit_Data[[#This Row],[Tenure]]>3,"3 to 6 Yrs",Exit_Data[[#This Row],[Tenure]]>1,"1 to 3 Yrs",Exit_Data[[#This Row],[Tenure]]>0,"0 to 1 Yr") -> 6 to 9 Yrs
A42: 41 | B42: 10144 | C42: Mike Ross | D42: M | E42: G2 | F42: Finance | G42: =IF(ISBLANK(Exit_Data[[#This Row],[Exit Date]]),"Active","Inactive") -> Active | H42: 44759 | L42: Anthony Bridgerton | M42: =(TODAY()-Exit_Data[[#This Row],[DOJ]])/365.25 -> 3.9589322 | N42: =_xlfn.IFS(Exit_Data[[#This Row],[Tenure]]>9,"9+ Yrs",Exit_Data[[#This Row],[Tenure]]>6,"6 to 9 Yrs",Exit_Data[[#This Row],[Tenure]]>3,"3 to 6 Yrs",Exit_Data[[#This Row],[Tenure]]>1,"1 to 3 Yrs",Exit_Data[[#This Row],[Tenure]]>0,"0 to 1 Yr") -> 3 to 6 Yrs
A43: 42 | B43: 10145 | C43: Louis Litt | D43: M | E43: G3 | F43: Finance | G43: =IF(ISBLANK(Exit_Data[[#This Row],[Exit Date]]),"Active","Inactive") -> Active | H43: 45202 | L43: Anthony Bridgerton | M43: =(TODAY()-Exit_Data[[#This Row],[DOJ]])/365.25 -> 2.7460643 | N43: =_xlfn.IFS(Exit_Data[[#This Row],[Tenure]]>9,"9+ Yrs",Exit_Data[[#This Row],[Tenure]]>6,"6 to 9 Yrs",Exit_Data[[#This Row],[Tenure]]>3,"3 to 6 Yrs",Exit_Data[[#This Row],[Tenure]]>1,"1 to 3 Yrs",Exit_Data[[#This Row],[Tenure]]>0,"0 to 1 Yr") -> 1 to 3 Yrs
A44: 43 | B44: 10146 | C44: Donna Paulsen | D44: F | E44: G3 | F44: Finance | G44: =IF(ISBLANK(Exit_Data[[#This Row],[Exit Date]]),"Active","Inactive") -> Inactive | H44: 44353 | I44: 45846 | J44: Voluntary | K44: Better Opportunity | L44: Anthony Bridgerton | M44: =(TODAY()-Exit_Data[[#This Row],[DOJ]])/365.25 -> 5.0704997 | N44: =_xlfn.IFS(Exit_Data[[#This Row],[Tenure]]>9,"9+ Yrs",Exit_Data[[#This Row],[Tenure]]>6,"6 to 9 Yrs",Exit_Data[[#This Row],[Tenure]]>3,"3 to 6 Yrs",Exit_Data[[#This Row],[Tenure]]>1,"1 to 3 Yrs",Exit_Data[[#This Row],[Tenure]]>0,"0 to 1 Yr") -> 3 to 6 Yrs
A45: 44 | B45: 10147 | C45: Jessica Pearson | D45: F | E45: G2 | F45: Marketing | G45: =IF(ISBLANK(Exit_Data[[#This Row],[Exit Date]]),"Active","Inactive") -> Inactive | H45: 43881 | I45: 45971 | J45: Voluntary | K45: Better Opportunity | L45: Camille Razat | M45: =(TODAY()-Exit_Data[[#This Row],[DOJ]])/365.25 -> 6.3627652 | N45: =_xlfn.IFS(Exit_Data[[#This Row],[Tenure]]>9,"9+ Yrs",Exit_Data[[#This Row],[Tenure]]>6,"6 to 9 Yrs",Exit_Data[[#This Row],[Tenure]]>3,"3 to 6 Yrs",Exit_Data[[#This Row],[Tenure]]>1,"1 to 3 Yrs",Exit_Data[[#This Row],[Tenure]]>0,"0 to 1 Yr") -> 6 to 9 Yrs
A46: 45 | B46: 10148 | C46: Rachel Zane | D46: F | E46: G1 | F46: Sales | G46: =IF(ISBLANK(Exit_Data[[#This Row],[Exit Date]]),"Active","Inactive") -> Active | H46: 44669 | L46: Margo Banks | M46: =(TODAY()-Exit_Data[[#This Row],[DOJ]])/365.25 -> 4.2053388 | N46: =_xlfn.IFS(Exit_Data[[#This Row],[Tenure]]>9,"9+ Yrs",Exit_Data[[#This Row],[Tenure]]>6,"6 to 9 Yrs",Exit_Data[[#This Row],[Tenure]]>3,"3 to 6 Yrs",Exit_Data[[#This Row],[Tenure]]>1,"1 to 3 Yrs",Exit_Data[[#This Row],[Tenure]]>0,"0 to 1 Yr") -> 3 to 6 Yrs
A47: 46 | B47: 10149 | C47: Katrina Bennett | D47: F | E47: G2 | F47: IT | G47: =IF(ISBLANK(Exit_Data[[#This Row],[Exit Date]]),"Active","Inactive") -> Active | H47: 44955 | L47: Simon Elroy | M47: =(TODAY()-Exit_Data[[#This Row],[DOJ]])/365.25 -> 3.4223135 | N47: =_xlfn.IFS(Exit_Data[[#This Row],[Tenure]]>9,"9+ Yrs",Exit_Data[[#This Row],[Tenure]]>6,"6 to 9 Yrs",Exit_Data[[#This Row],[Tenure]]>3,"3 to 6 Yrs",Exit_Data[[#This Row],[Tenure]]>1,"1 to 3 Yrs",Exit_Data[[#This Row],[Tenure]]>0,"0 to 1 Yr") -> 3 to 6 Yrs
A48: 47 | B48: 10150 | C48: Samantha Wheeler | D48: F | E48: G1 | F48: Marketing | G48: =IF(ISBLANK(Exit_Data[[#This Row],[Exit Date]]),"Active","Inactive") -> Active | H48: 44269 | L48: Emily Cooper | M48: =(TODAY()-Exit_Data[[#This Row],[DOJ]])/365.25 -> 5.3004791 | N48: =_xlfn.IFS(Exit_Data[[#This Row],[Tenure]]>9,"9+ Yrs",Exit_Data[[#This Row],[Tenure]]>6,"6 to 9 Yrs",Exit_Data[[#This Row],[Tenure]]>3,"3 to 6 Yrs",Exit_Data[[#This Row],[Tenure]]>1,"1 to 3 Yrs",Exit_Data[[#This Row],[Tenure]]>0,"0 to 1 Yr") -> 3 to 6 Yrs
A49: 48 | B49: 10151 | C49: Robert Zane | D49: M | E49: G2 | F49: Marketing | G49: =IF(ISBLANK(Exit_Data[[#This Row],[Exit Date]]),"Active","Inactive") -> Active | H49: 44065 | L49: Emily Cooper | M49: =(TODAY()-Exit_Data[[#This Row],[DOJ]])/365.25 -> 5.8590007 | N49: =_xlfn.IFS(Exit_Data[[#This Row],[Tenure]]>9,"9+ Yrs",Exit_Data[[#This Row],[Tenure]]>6,"6 to 9 Yrs",Exit_Data[[#This Row],[Tenure]]>3,"3 to 6 Yrs",Exit_Data[[#This Row],[Tenure]]>1,"1 to 3 Yrs",Exit_Data[[#This Row],[Tenure]]>0,"0 to 1 Yr") -> 3 to 6 Yrs
...
